I /usr/lib/python3/dist-packages/werkzeug/_internal.py:113  * Running on http://0.0.0.0:5000/ (Press CTRL+C to quit)
I /usr/lib/python3/dist-packages/werkzeug/_internal.py:113 192.168.10.43 - - [02/Mar/2025 13:51:12] "[32mGET / HTTP/1.1[0m" 302 -
I /usr/lib/python3/dist-packages/werkzeug/_internal.py:113 192.168.10.43 - - [02/Mar/2025 13:51:12] "[37mGET /login HTTP/1.1[0m" 200 -
I /usr/lib/python3/dist-packages/werkzeug/_internal.py:113 192.168.10.43 - - [02/Mar/2025 13:51:12] "[37mGET /static/images/cat.png HTTP/1.1[0m" 200 -
I /usr/lib/python3/dist-packages/werkzeug/_internal.py:113 192.168.10.43 - - [02/Mar/2025 13:51:12] "[37mGET /static/css/style.css HTTP/1.1[0m" 200 -
I /usr/lib/python3/dist-packages/werkzeug/_internal.py:113 192.168.10.43 - - [02/Mar/2025 13:51:13] "[37mGET /static/images/key.png HTTP/1.1[0m" 200 -
I /usr/lib/python3/dist-packages/werkzeug/_internal.py:113 192.168.10.43 - - [02/Mar/2025 13:51:13] "[37mGET /static/images/adm.png HTTP/1.1[0m" 200 -
I /usr/lib/python3/dist-packages/werkzeug/_internal.py:113 192.168.10.43 - - [02/Mar/2025 13:51:13] "[37mGET /static/images/pass.png HTTP/1.1[0m" 200 -
I /usr/lib/python3/dist-packages/werkzeug/_internal.py:113 192.168.10.43 - - [02/Mar/2025 13:51:13] "[37mGET /static/images/close.png HTTP/1.1[0m" 200 -
I /usr/lib/python3/dist-packages/werkzeug/_internal.py:113 192.168.10.43 - - [02/Mar/2025 13:51:13] "[37mGET /static/images/bg1.jpg HTTP/1.1[0m" 200 -
I /usr/lib/python3/dist-packages/werkzeug/_internal.py:113 192.168.10.43 - - [02/Mar/2025 13:51:13] "[33mGET /favicon.ico HTTP/1.1[0m" 404 -
I /usr/lib/python3/dist-packages/werkzeug/_internal.py:113 192.168.10.43 - - [02/Mar/2025 13:51:14] "[37mPOST /login HTTP/1.1[0m" 200 -
I /usr/lib/python3/dist-packages/werkzeug/_internal.py:113 192.168.10.43 - - [02/Mar/2025 13:52:52] "[32mPOST /login HTTP/1.1[0m" 302 -
I /usr/lib/python3/dist-packages/werkzeug/_internal.py:113 192.168.10.43 - - [02/Mar/2025 13:52:52] "[37mGET / HTTP/1.1[0m" 200 -
I /usr/lib/python3/dist-packages/werkzeug/_internal.py:113 192.168.10.43 - - [02/Mar/2025 13:52:52] "[37mGET /static/button_process.js HTTP/1.1[0m" 200 -
I /usr/lib/python3/dist-packages/werkzeug/_internal.py:113 192.168.10.43 - - [02/Mar/2025 13:52:53] "[37mGET /video_viewer HTTP/1.1[0m" 200 -
I /usr/lib/python3/dist-packages/werkzeug/_internal.py:113 192.168.10.43 - - [02/Mar/2025 13:53:05] "[37mPOST /process_status HTTP/1.1[0m" 200 -
E /usr/lib/python3/dist-packages/werkzeug/_internal.py:113 Error on request:
Traceback (most recent call last):
  File "/usr/lib/python3/dist-packages/werkzeug/serving.py", line 323, in run_wsgi
    execute(self.server.app)
  File "/usr/lib/python3/dist-packages/werkzeug/serving.py", line 314, in execute
    for data in application_iter:
  File "/usr/lib/python3/dist-packages/werkzeug/wsgi.py", line 506, in __next__
    return self._next()
  File "/usr/lib/python3/dist-packages/werkzeug/wrappers/base_response.py", line 45, in _iter_encoded
    for item in iterable:
  File "/home/orangepi/lubancat-rk_code-ai/flask-opencv-rknn/controller/modules/home/views.py", line 29, in video_stream
    frame = video_camera.get_frame()
  File "/home/orangepi/lubancat-rk_code-ai/flask-opencv-rknn/controller/utils/camera.py", line 75, in get_frame
    self.frame = process_image(self.image, self.outputs)
  File "/home/orangepi/lubancat-rk_code-ai/flask-opencv-rknn/controller/utils/rknn_image.py", line 227, in process_image
    input0_data = outputs[0]
TypeError: 'NoneType' object is not subscriptable
I /usr/lib/python3/dist-packages/werkzeug/_internal.py:113  * Running on http://0.0.0.0:5000/ (Press CTRL+C to quit)
I /usr/lib/python3/dist-packages/werkzeug/_internal.py:113 192.168.10.43 - - [02/Mar/2025 13:55:35] "[37mGET / HTTP/1.1[0m" 200 -
I /usr/lib/python3/dist-packages/werkzeug/_internal.py:113 192.168.10.43 - - [02/Mar/2025 13:55:36] "[37mGET /video_viewer HTTP/1.1[0m" 200 -
I /usr/lib/python3/dist-packages/werkzeug/_internal.py:113  * Running on http://0.0.0.0:5000/ (Press CTRL+C to quit)
E /usr/lib/python3/dist-packages/flask/app.py:1891 Exception on / [GET]
Traceback (most recent call last):
  File "/usr/lib/python3/dist-packages/flask/app.py", line 2447, in wsgi_app
    response = self.full_dispatch_request()
  File "/usr/lib/python3/dist-packages/flask/app.py", line 1952, in full_dispatch_request
    rv = self.handle_user_exception(e)
  File "/usr/lib/python3/dist-packages/flask/app.py", line 1821, in handle_user_exception
    reraise(exc_type, exc_value, tb)
  File "/usr/lib/python3/dist-packages/flask/_compat.py", line 39, in reraise
    raise value
  File "/usr/lib/python3/dist-packages/flask/app.py", line 1950, in full_dispatch_request
    rv = self.dispatch_request()
  File "/usr/lib/python3/dist-packages/flask/app.py", line 1936, in dispatch_request
    return self.view_functions[rule.endpoint](**req.view_args)
  File "/home/orangepi/lubancat-rk_code-ai/flask-opencv-rknn/controller/modules/home/views.py", line 17, in index
    return render_template("index.html")
  File "/usr/lib/python3/dist-packages/flask/templating.py", line 138, in render_template
    ctx.app.jinja_env.get_or_select_template(template_name_or_list),
  File "/usr/lib/python3/dist-packages/jinja2/environment.py", line 930, in get_or_select_template
    return self.get_template(template_name_or_list, parent, globals)
  File "/usr/lib/python3/dist-packages/jinja2/environment.py", line 883, in get_template
    return self._load_template(name, self.make_globals(globals))
  File "/usr/lib/python3/dist-packages/jinja2/environment.py", line 857, in _load_template
    template = self.loader.load(self, name, globals)
  File "/usr/lib/python3/dist-packages/jinja2/loaders.py", line 115, in load
    source, filename, uptodate = self.get_source(environment, name)
  File "/usr/lib/python3/dist-packages/flask/templating.py", line 60, in get_source
    return self._get_source_fast(environment, template)
  File "/usr/lib/python3/dist-packages/flask/templating.py", line 86, in _get_source_fast
    return loader.get_source(environment, template)
  File "/usr/lib/python3/dist-packages/jinja2/loaders.py", line 184, in get_source
    contents = f.read().decode(self.encoding)
UnicodeDecodeError: 'utf-8' codec can't decode byte 0xec in position 542: invalid continuation byte
I /usr/lib/python3/dist-packages/werkzeug/_internal.py:113 192.168.10.43 - - [02/Mar/2025 13:58:55] "[35m[1mGET / HTTP/1.1[0m" 500 -
E /usr/lib/python3/dist-packages/flask/app.py:1891 Exception on / [GET]
Traceback (most recent call last):
  File "/usr/lib/python3/dist-packages/flask/app.py", line 2447, in wsgi_app
    response = self.full_dispatch_request()
  File "/usr/lib/python3/dist-packages/flask/app.py", line 1952, in full_dispatch_request
    rv = self.handle_user_exception(e)
  File "/usr/lib/python3/dist-packages/flask/app.py", line 1821, in handle_user_exception
    reraise(exc_type, exc_value, tb)
  File "/usr/lib/python3/dist-packages/flask/_compat.py", line 39, in reraise
    raise value
  File "/usr/lib/python3/dist-packages/flask/app.py", line 1950, in full_dispatch_request
    rv = self.dispatch_request()
  File "/usr/lib/python3/dist-packages/flask/app.py", line 1936, in dispatch_request
    return self.view_functions[rule.endpoint](**req.view_args)
  File "/home/orangepi/lubancat-rk_code-ai/flask-opencv-rknn/controller/modules/home/views.py", line 17, in index
    return render_template("index.html")
  File "/usr/lib/python3/dist-packages/flask/templating.py", line 138, in render_template
    ctx.app.jinja_env.get_or_select_template(template_name_or_list),
  File "/usr/lib/python3/dist-packages/jinja2/environment.py", line 930, in get_or_select_template
    return self.get_template(template_name_or_list, parent, globals)
  File "/usr/lib/python3/dist-packages/jinja2/environment.py", line 883, in get_template
    return self._load_template(name, self.make_globals(globals))
  File "/usr/lib/python3/dist-packages/jinja2/environment.py", line 857, in _load_template
    template = self.loader.load(self, name, globals)
  File "/usr/lib/python3/dist-packages/jinja2/loaders.py", line 115, in load
    source, filename, uptodate = self.get_source(environment, name)
  File "/usr/lib/python3/dist-packages/flask/templating.py", line 60, in get_source
    return self._get_source_fast(environment, template)
  File "/usr/lib/python3/dist-packages/flask/templating.py", line 86, in _get_source_fast
    return loader.get_source(environment, template)
  File "/usr/lib/python3/dist-packages/jinja2/loaders.py", line 184, in get_source
    contents = f.read().decode(self.encoding)
UnicodeDecodeError: 'utf-8' codec can't decode byte 0xec in position 542: invalid continuation byte
I /usr/lib/python3/dist-packages/werkzeug/_internal.py:113 192.168.10.43 - - [02/Mar/2025 13:58:58] "[35m[1mGET / HTTP/1.1[0m" 500 -
E /usr/lib/python3/dist-packages/flask/app.py:1891 Exception on / [GET]
Traceback (most recent call last):
  File "/usr/lib/python3/dist-packages/flask/app.py", line 2447, in wsgi_app
    response = self.full_dispatch_request()
  File "/usr/lib/python3/dist-packages/flask/app.py", line 1952, in full_dispatch_request
    rv = self.handle_user_exception(e)
  File "/usr/lib/python3/dist-packages/flask/app.py", line 1821, in handle_user_exception
    reraise(exc_type, exc_value, tb)
  File "/usr/lib/python3/dist-packages/flask/_compat.py", line 39, in reraise
    raise value
  File "/usr/lib/python3/dist-packages/flask/app.py", line 1950, in full_dispatch_request
    rv = self.dispatch_request()
  File "/usr/lib/python3/dist-packages/flask/app.py", line 1936, in dispatch_request
    return self.view_functions[rule.endpoint](**req.view_args)
  File "/home/orangepi/lubancat-rk_code-ai/flask-opencv-rknn/controller/modules/home/views.py", line 17, in index
    return render_template("index.html")
  File "/usr/lib/python3/dist-packages/flask/templating.py", line 138, in render_template
    ctx.app.jinja_env.get_or_select_template(template_name_or_list),
  File "/usr/lib/python3/dist-packages/jinja2/environment.py", line 930, in get_or_select_template
    return self.get_template(template_name_or_list, parent, globals)
  File "/usr/lib/python3/dist-packages/jinja2/environment.py", line 883, in get_template
    return self._load_template(name, self.make_globals(globals))
  File "/usr/lib/python3/dist-packages/jinja2/environment.py", line 857, in _load_template
    template = self.loader.load(self, name, globals)
  File "/usr/lib/python3/dist-packages/jinja2/loaders.py", line 115, in load
    source, filename, uptodate = self.get_source(environment, name)
  File "/usr/lib/python3/dist-packages/flask/templating.py", line 60, in get_source
    return self._get_source_fast(environment, template)
  File "/usr/lib/python3/dist-packages/flask/templating.py", line 86, in _get_source_fast
    return loader.get_source(environment, template)
  File "/usr/lib/python3/dist-packages/jinja2/loaders.py", line 184, in get_source
    contents = f.read().decode(self.encoding)
UnicodeDecodeError: 'utf-8' codec can't decode byte 0xec in position 542: invalid continuation byte
I /usr/lib/python3/dist-packages/werkzeug/_internal.py:113 192.168.10.43 - - [02/Mar/2025 13:59:31] "[35m[1mGET / HTTP/1.1[0m" 500 -
I /usr/lib/python3/dist-packages/werkzeug/_internal.py:113  * Running on http://0.0.0.0:5000/ (Press CTRL+C to quit)
E /usr/lib/python3/dist-packages/flask/app.py:1891 Exception on / [GET]
Traceback (most recent call last):
  File "/usr/lib/python3/dist-packages/flask/app.py", line 2447, in wsgi_app
    response = self.full_dispatch_request()
  File "/usr/lib/python3/dist-packages/flask/app.py", line 1952, in full_dispatch_request
    rv = self.handle_user_exception(e)
  File "/usr/lib/python3/dist-packages/flask/app.py", line 1821, in handle_user_exception
    reraise(exc_type, exc_value, tb)
  File "/usr/lib/python3/dist-packages/flask/_compat.py", line 39, in reraise
    raise value
  File "/usr/lib/python3/dist-packages/flask/app.py", line 1950, in full_dispatch_request
    rv = self.dispatch_request()
  File "/usr/lib/python3/dist-packages/flask/app.py", line 1936, in dispatch_request
    return self.view_functions[rule.endpoint](**req.view_args)
  File "/home/orangepi/lubancat-rk_code-ai/flask-opencv-rknn/controller/modules/home/views.py", line 17, in index
    return render_template("index.html")
  File "/usr/lib/python3/dist-packages/flask/templating.py", line 138, in render_template
    ctx.app.jinja_env.get_or_select_template(template_name_or_list),
  File "/usr/lib/python3/dist-packages/jinja2/environment.py", line 930, in get_or_select_template
    return self.get_template(template_name_or_list, parent, globals)
  File "/usr/lib/python3/dist-packages/jinja2/environment.py", line 883, in get_template
    return self._load_template(name, self.make_globals(globals))
  File "/usr/lib/python3/dist-packages/jinja2/environment.py", line 857, in _load_template
    template = self.loader.load(self, name, globals)
  File "/usr/lib/python3/dist-packages/jinja2/loaders.py", line 115, in load
    source, filename, uptodate = self.get_source(environment, name)
  File "/usr/lib/python3/dist-packages/flask/templating.py", line 60, in get_source
    return self._get_source_fast(environment, template)
  File "/usr/lib/python3/dist-packages/flask/templating.py", line 86, in _get_source_fast
    return loader.get_source(environment, template)
  File "/usr/lib/python3/dist-packages/jinja2/loaders.py", line 184, in get_source
    contents = f.read().decode(self.encoding)
UnicodeDecodeError: 'utf-8' codec can't decode byte 0xec in position 542: invalid continuation byte
I /usr/lib/python3/dist-packages/werkzeug/_internal.py:113 192.168.10.43 - - [02/Mar/2025 14:01:32] "[35m[1mGET / HTTP/1.1[0m" 500 -
I /usr/lib/python3/dist-packages/werkzeug/_internal.py:113  * Running on http://0.0.0.0:5000/ (Press CTRL+C to quit)
I /usr/lib/python3/dist-packages/werkzeug/_internal.py:113 192.168.10.43 - - [02/Mar/2025 14:04:22] "[37mGET / HTTP/1.1[0m" 200 -
I /usr/lib/python3/dist-packages/werkzeug/_internal.py:113 192.168.10.43 - - [02/Mar/2025 14:04:23] "[37mGET /video_viewer HTTP/1.1[0m" 200 -
I /usr/lib/python3/dist-packages/werkzeug/_internal.py:113 192.168.10.43 - - [02/Mar/2025 14:04:26] "[32mGET /logout HTTP/1.1[0m" 302 -
I /usr/lib/python3/dist-packages/werkzeug/_internal.py:113 192.168.10.43 - - [02/Mar/2025 14:04:26] "[37mGET /login HTTP/1.1[0m" 200 -
I /usr/lib/python3/dist-packages/werkzeug/_internal.py:113 192.168.10.43 - - [02/Mar/2025 14:05:13] "[37mGET /login HTTP/1.1[0m" 200 -
I /usr/lib/python3/dist-packages/werkzeug/_internal.py:113 192.168.10.43 - - [02/Mar/2025 14:05:22] "[37mPOST /login HTTP/1.1[0m" 200 -
I /usr/lib/python3/dist-packages/werkzeug/_internal.py:113 192.168.10.43 - - [02/Mar/2025 14:05:24] "[37mPOST /login HTTP/1.1[0m" 200 -
I /usr/lib/python3/dist-packages/werkzeug/_internal.py:113 192.168.10.43 - - [02/Mar/2025 14:05:26] "[37mPOST /login HTTP/1.1[0m" 200 -
I /usr/lib/python3/dist-packages/werkzeug/_internal.py:113 192.168.10.43 - - [02/Mar/2025 14:05:27] "[37mPOST /login HTTP/1.1[0m" 200 -
I /usr/lib/python3/dist-packages/werkzeug/_internal.py:113 192.168.10.43 - - [02/Mar/2025 14:05:37] "[32mPOST /login HTTP/1.1[0m" 302 -
I /usr/lib/python3/dist-packages/werkzeug/_internal.py:113 192.168.10.43 - - [02/Mar/2025 14:05:37] "[37mGET / HTTP/1.1[0m" 200 -
I /usr/lib/python3/dist-packages/werkzeug/_internal.py:113 192.168.10.43 - - [02/Mar/2025 14:05:37] "[37mGET /video_viewer HTTP/1.1[0m" 200 -
I /usr/lib/python3/dist-packages/werkzeug/_internal.py:113 192.168.10.43 - - [02/Mar/2025 14:05:42] "[37mPOST /process_status HTTP/1.1[0m" 200 -
E /usr/lib/python3/dist-packages/werkzeug/_internal.py:113 Error on request:
Traceback (most recent call last):
  File "/usr/lib/python3/dist-packages/werkzeug/serving.py", line 323, in run_wsgi
    execute(self.server.app)
  File "/usr/lib/python3/dist-packages/werkzeug/serving.py", line 314, in execute
    for data in application_iter:
  File "/usr/lib/python3/dist-packages/werkzeug/wsgi.py", line 506, in __next__
    return self._next()
  File "/usr/lib/python3/dist-packages/werkzeug/wrappers/base_response.py", line 45, in _iter_encoded
    for item in iterable:
  File "/home/orangepi/lubancat-rk_code-ai/flask-opencv-rknn/controller/modules/home/views.py", line 29, in video_stream
    frame = video_camera.get_frame()
  File "/home/orangepi/lubancat-rk_code-ai/flask-opencv-rknn/controller/utils/camera.py", line 75, in get_frame
    self.frame = process_image(self.image, self.outputs)
  File "/home/orangepi/lubancat-rk_code-ai/flask-opencv-rknn/controller/utils/rknn_image.py", line 227, in process_image
    input0_data = outputs[0]
TypeError: 'NoneType' object is not subscriptable
I /usr/lib/python3/dist-packages/werkzeug/_internal.py:113  * Running on http://0.0.0.0:5000/ (Press CTRL+C to quit)
I /usr/lib/python3/dist-packages/werkzeug/_internal.py:113 192.168.10.43 - - [02/Mar/2025 14:06:24] "[37mGET / HTTP/1.1[0m" 200 -
I /usr/lib/python3/dist-packages/werkzeug/_internal.py:113 192.168.10.43 - - [02/Mar/2025 14:06:25] "[37mGET /video_viewer HTTP/1.1[0m" 200 -
I /usr/lib/python3/dist-packages/werkzeug/_internal.py:113  * Running on http://0.0.0.0:5000/ (Press CTRL+C to quit)
I /usr/lib/python3/dist-packages/werkzeug/_internal.py:113 192.168.10.43 - - [02/Mar/2025 14:10:42] "[37mGET / HTTP/1.1[0m" 200 -
I /usr/lib/python3/dist-packages/werkzeug/_internal.py:113 192.168.10.43 - - [02/Mar/2025 14:10:43] "[37mGET /video_viewer HTTP/1.1[0m" 200 -
I /usr/lib/python3/dist-packages/werkzeug/_internal.py:113 192.168.10.43 - - [02/Mar/2025 14:11:04] "[37mPOST /record_status HTTP/1.1[0m" 200 -
I /usr/lib/python3/dist-packages/werkzeug/_internal.py:113 192.168.10.43 - - [02/Mar/2025 14:11:15] "[37mPOST /record_status HTTP/1.1[0m" 200 -
I /usr/lib/python3/dist-packages/werkzeug/_internal.py:113 192.168.10.43 - - [02/Mar/2025 14:11:25] "[37mPOST /process_status HTTP/1.1[0m" 200 -
E /usr/lib/python3/dist-packages/werkzeug/_internal.py:113 Error on request:
Traceback (most recent call last):
  File "/usr/lib/python3/dist-packages/werkzeug/serving.py", line 323, in run_wsgi
    execute(self.server.app)
  File "/usr/lib/python3/dist-packages/werkzeug/serving.py", line 314, in execute
    for data in application_iter:
  File "/usr/lib/python3/dist-packages/werkzeug/wsgi.py", line 506, in __next__
    return self._next()
  File "/usr/lib/python3/dist-packages/werkzeug/wrappers/base_response.py", line 45, in _iter_encoded
    for item in iterable:
  File "/home/orangepi/lubancat-rk_code-ai/flask-opencv-rknn/controller/modules/home/views.py", line 29, in video_stream
    frame = video_camera.get_frame()
  File "/home/orangepi/lubancat-rk_code-ai/flask-opencv-rknn/controller/utils/camera.py", line 75, in get_frame
    self.frame = process_image(self.image, self.outputs)
  File "/home/orangepi/lubancat-rk_code-ai/flask-opencv-rknn/controller/utils/rknn_image.py", line 227, in process_image
    input0_data = outputs[0]
TypeError: 'NoneType' object is not subscriptable
I /usr/lib/python3/dist-packages/werkzeug/_internal.py:113  * Running on http://0.0.0.0:5000/ (Press CTRL+C to quit)
I /usr/lib/python3/dist-packages/werkzeug/_internal.py:113 192.168.10.43 - - [02/Mar/2025 14:16:55] "[37mGET / HTTP/1.1[0m" 200 -
I /usr/lib/python3/dist-packages/werkzeug/_internal.py:113 192.168.10.43 - - [02/Mar/2025 14:16:56] "[37mGET /video_viewer HTTP/1.1[0m" 200 -
I /usr/lib/python3/dist-packages/werkzeug/_internal.py:113 192.168.10.43 - - [02/Mar/2025 14:18:04] "[37mPOST /process_status HTTP/1.1[0m" 200 -
E /usr/lib/python3/dist-packages/werkzeug/_internal.py:113 Error on request:
Traceback (most recent call last):
  File "/usr/lib/python3/dist-packages/werkzeug/serving.py", line 323, in run_wsgi
    execute(self.server.app)
  File "/usr/lib/python3/dist-packages/werkzeug/serving.py", line 314, in execute
    for data in application_iter:
  File "/usr/lib/python3/dist-packages/werkzeug/wsgi.py", line 506, in __next__
    return self._next()
  File "/usr/lib/python3/dist-packages/werkzeug/wrappers/base_response.py", line 45, in _iter_encoded
    for item in iterable:
  File "/home/orangepi/lubancat-rk_code-ai/flask-opencv-rknn/controller/modules/home/views.py", line 29, in video_stream
    frame = video_camera.get_frame()
  File "/home/orangepi/lubancat-rk_code-ai/flask-opencv-rknn/controller/utils/camera.py", line 75, in get_frame
    self.frame = process_image(self.image, self.outputs)
  File "/home/orangepi/lubancat-rk_code-ai/flask-opencv-rknn/controller/utils/rknn_image.py", line 227, in process_image
    input0_data = outputs[0]
TypeError: 'NoneType' object is not subscriptable
I /usr/lib/python3/dist-packages/werkzeug/_internal.py:113  * Running on http://0.0.0.0:5000/ (Press CTRL+C to quit)
I /usr/lib/python3/dist-packages/werkzeug/_internal.py:113 192.168.10.43 - - [02/Mar/2025 14:26:54] "[37mGET / HTTP/1.1[0m" 200 -
I /usr/lib/python3/dist-packages/werkzeug/_internal.py:113 192.168.10.43 - - [02/Mar/2025 14:26:55] "[37mGET /video_viewer HTTP/1.1[0m" 200 -
I /usr/lib/python3/dist-packages/werkzeug/_internal.py:113 192.168.10.43 - - [02/Mar/2025 14:26:57] "[37mPOST /process_status HTTP/1.1[0m" 200 -
E /usr/lib/python3/dist-packages/werkzeug/_internal.py:113 Error on request:
Traceback (most recent call last):
  File "/usr/lib/python3/dist-packages/werkzeug/serving.py", line 323, in run_wsgi
    execute(self.server.app)
  File "/usr/lib/python3/dist-packages/werkzeug/serving.py", line 314, in execute
    for data in application_iter:
  File "/usr/lib/python3/dist-packages/werkzeug/wsgi.py", line 506, in __next__
    return self._next()
  File "/usr/lib/python3/dist-packages/werkzeug/wrappers/base_response.py", line 45, in _iter_encoded
    for item in iterable:
  File "/home/orangepi/lubancat-rk_code-ai/flask-opencv-rknn/controller/modules/home/views.py", line 29, in video_stream
    frame = video_camera.get_frame()
  File "/home/orangepi/lubancat-rk_code-ai/flask-opencv-rknn/controller/utils/camera.py", line 73, in get_frame
    self.frame = process_image(self.image, self.outputs)
  File "/home/orangepi/lubancat-rk_code-ai/flask-opencv-rknn/controller/utils/rknn_image.py", line 227, in process_image
    input0_data = outputs[0]
TypeError: 'NoneType' object is not subscriptable
I /usr/lib/python3/dist-packages/werkzeug/_internal.py:113 192.168.10.43 - - [02/Mar/2025 14:27:01] "[37mPOST /process_status HTTP/1.1[0m" 200 -
I /usr/lib/python3/dist-packages/werkzeug/_internal.py:113 192.168.10.43 - - [02/Mar/2025 14:27:06] "[37mPOST /process_status HTTP/1.1[0m" 200 -
I /usr/lib/python3/dist-packages/werkzeug/_internal.py:113 192.168.10.43 - - [02/Mar/2025 14:27:32] "[37mGET / HTTP/1.1[0m" 200 -
I /usr/lib/python3/dist-packages/werkzeug/_internal.py:113 192.168.10.43 - - [02/Mar/2025 14:27:32] "[35m[1mGET /video_viewer HTTP/1.1[0m" 500 -
E /usr/lib/python3/dist-packages/werkzeug/_internal.py:113 Error on request:
Traceback (most recent call last):
  File "/usr/lib/python3/dist-packages/werkzeug/serving.py", line 323, in run_wsgi
    execute(self.server.app)
  File "/usr/lib/python3/dist-packages/werkzeug/serving.py", line 314, in execute
    for data in application_iter:
  File "/usr/lib/python3/dist-packages/werkzeug/wsgi.py", line 506, in __next__
    return self._next()
  File "/usr/lib/python3/dist-packages/werkzeug/wrappers/base_response.py", line 45, in _iter_encoded
    for item in iterable:
  File "/home/orangepi/lubancat-rk_code-ai/flask-opencv-rknn/controller/modules/home/views.py", line 29, in video_stream
    frame = video_camera.get_frame()
  File "/home/orangepi/lubancat-rk_code-ai/flask-opencv-rknn/controller/utils/camera.py", line 73, in get_frame
    self.frame = process_image(self.image, self.outputs)
  File "/home/orangepi/lubancat-rk_code-ai/flask-opencv-rknn/controller/utils/rknn_image.py", line 227, in process_image
    input0_data = outputs[0]
TypeError: 'NoneType' object is not subscriptable
I /usr/lib/python3/dist-packages/werkzeug/_internal.py:113  * Running on http://0.0.0.0:5000/ (Press CTRL+C to quit)
I /usr/lib/python3/dist-packages/werkzeug/_internal.py:113 192.168.10.43 - - [02/Mar/2025 14:29:35] "[37mGET / HTTP/1.1[0m" 200 -
I /usr/lib/python3/dist-packages/werkzeug/_internal.py:113 192.168.10.43 - - [02/Mar/2025 14:29:36] "[37mGET /video_viewer HTTP/1.1[0m" 200 -
I /usr/lib/python3/dist-packages/werkzeug/_internal.py:113 192.168.10.43 - - [02/Mar/2025 14:29:38] "[37mPOST /process_status HTTP/1.1[0m" 200 -
E /usr/lib/python3/dist-packages/werkzeug/_internal.py:113 Error on request:
Traceback (most recent call last):
  File "/usr/lib/python3/dist-packages/werkzeug/serving.py", line 323, in run_wsgi
    execute(self.server.app)
  File "/usr/lib/python3/dist-packages/werkzeug/serving.py", line 314, in execute
    for data in application_iter:
  File "/usr/lib/python3/dist-packages/werkzeug/wsgi.py", line 506, in __next__
    return self._next()
  File "/usr/lib/python3/dist-packages/werkzeug/wrappers/base_response.py", line 45, in _iter_encoded
    for item in iterable:
  File "/home/orangepi/lubancat-rk_code-ai/flask-opencv-rknn/controller/modules/home/views.py", line 29, in video_stream
    frame = video_camera.get_frame()
  File "/home/orangepi/lubancat-rk_code-ai/flask-opencv-rknn/controller/utils/camera.py", line 73, in get_frame
    self.frame = process_image(self.image, self.outputs)
  File "/home/orangepi/lubancat-rk_code-ai/flask-opencv-rknn/controller/utils/rknn_image.py", line 227, in process_image
    input0_data = outputs[0]
TypeError: 'NoneType' object is not subscriptable
I /usr/lib/python3/dist-packages/werkzeug/_internal.py:113  * Running on http://0.0.0.0:5000/ (Press CTRL+C to quit)
I /usr/lib/python3/dist-packages/werkzeug/_internal.py:113 192.168.10.43 - - [02/Mar/2025 14:33:19] "[37mGET / HTTP/1.1[0m" 200 -
I /usr/lib/python3/dist-packages/werkzeug/_internal.py:113 192.168.10.43 - - [02/Mar/2025 14:33:20] "[37mGET /video_viewer HTTP/1.1[0m" 200 -
I /usr/lib/python3/dist-packages/werkzeug/_internal.py:113 192.168.10.43 - - [02/Mar/2025 14:33:22] "[37mPOST /process_status HTTP/1.1[0m" 200 -
E /usr/lib/python3/dist-packages/werkzeug/_internal.py:113 Error on request:
Traceback (most recent call last):
  File "/usr/lib/python3/dist-packages/werkzeug/serving.py", line 323, in run_wsgi
    execute(self.server.app)
  File "/usr/lib/python3/dist-packages/werkzeug/serving.py", line 314, in execute
    for data in application_iter:
  File "/usr/lib/python3/dist-packages/werkzeug/wsgi.py", line 506, in __next__
    return self._next()
  File "/usr/lib/python3/dist-packages/werkzeug/wrappers/base_response.py", line 45, in _iter_encoded
    for item in iterable:
  File "/home/orangepi/lubancat-rk_code-ai/flask-opencv-rknn/controller/modules/home/views.py", line 29, in video_stream
    frame = video_camera.get_frame()
  File "/home/orangepi/lubancat-rk_code-ai/flask-opencv-rknn/controller/utils/camera.py", line 66, in get_frame
    self.frame = process_image(self.image, self.outputs)
  File "/home/orangepi/lubancat-rk_code-ai/flask-opencv-rknn/controller/utils/rknn_image.py", line 227, in process_image
    input0_data = outputs[0]
TypeError: 'NoneType' object is not subscriptable
I /usr/lib/python3/dist-packages/werkzeug/_internal.py:113  * Running on http://0.0.0.0:5000/ (Press CTRL+C to quit)
I /usr/lib/python3/dist-packages/werkzeug/_internal.py:113 192.168.10.43 - - [02/Mar/2025 14:39:19] "[37mGET / HTTP/1.1[0m" 200 -
I /usr/lib/python3/dist-packages/werkzeug/_internal.py:113 192.168.10.43 - - [02/Mar/2025 14:39:20] "[37mGET /video_viewer HTTP/1.1[0m" 200 -
I /usr/lib/python3/dist-packages/werkzeug/_internal.py:113 192.168.10.43 - - [02/Mar/2025 14:39:22] "[37mPOST /process_status HTTP/1.1[0m" 200 -
